<?xml version="1.0"?>
<robot xmlns:xacro="http://ros.org/wiki/xacro">

  <xacro:include filename="$(find robot_description)/robot/parts/knuckle/knuckle.gazebo"/>
  
  <xacro:macro name="knuckle" params="prefix parent *joint_origin *joint_axis">
	<joint name="${prefix}_knuckle_joint" type="revolute">
	  <xacro:insert_block name="joint_origin"/>
	  <parent link="${parent}"/>
	  <child link="${prefix}_knuckle_link"/>
          <limit effort="200" velocity="3" lower="-1.51" upper = "1.51"/>
          <dynamics damping="0.005" friction="0.1"/>
	  <xacro:insert_block name="joint_axis"/>
	</joint>

	<link name="${prefix}_knuckle_link">
	  <visual>
		  <geometry>
		    <mesh filename="package://robot_description/meshes/STL/knuckle/knuckle.stl"/>
		  </geometry>
	  </visual>

	  <collision>
		  <geometry>
		    <mesh filename="package://robot_description/meshes/STL/knuckle/knuckle.stl"/>
		  </geometry>
	  </collision>
	  
    <inertial>
		<origin xyz="0.0 -0.011 -0.0"/>
		<mass value="0.25"/>
		<inertia ixx="0.00031" ixy="0" ixz="0" iyy="0.0005" iyz="0" izz="0.00031"/>
	  </inertial>
          <surface>
            <friction>
              <ode>
                <mu1>1.2</mu1>
                <mu2>1.2</mu2>
                <kp>1e15</kp>
                <kd>1e13</kd>
              </ode>
            </friction>
            <bounce>
              <restitution_coefficient>0.01</restitution_coefficient>
              <threshold>0</threshold>
            </bounce>
            <contact>
              <ode>
                <max_vel>10</max_vel>
              </ode>
            </contact>
          </surface>
	</link>
  </xacro:macro>
  
</robot>
